<?xml version="1.0"?>
<robot name="micro_sub" xmlns:xacro="http://www.ros.org/wiki/xacro">

  <link name="base_link">

    <collision>
      <origin xyz="0 0 0" rpy="0 0 0"/>
      <geometry>
        <box size="0.13335 0.17145 0.08255"/>
      </geometry>
    </collision>

    <visual>
      <origin xyz="0 0 0" rpy="0 0 0"/>
      <geometry>
        <box size="0.13335 0.17145 0.08255"/>
      </geometry>
    </visual>

    <inertial>
      <origin xyz="0 0 0" rpy="0 0 0"/>
      <mass value="1"/>
      <inertia
        ixx="1.0" ixy="0.0" ixz="0.0"
        iyy="1.0" iyz="0.0"
        izz="1.0"/>
    </inertial>

  </link>

  <link name="front_thruster_link">
    <visual>
      <origin xyz="0 0 0" rpy="0 0 0"/>
      <geometry>
        <cylinder radius="0.02" length="0.03"/>
      </geometry>
    </visual>
  </link>

  <link name="back_thruster_link">
    <visual>
      <origin xyz="0 0 0" rpy="0 0 0"/>
      <geometry>
        <cylinder radius="0.02" length="0.03"/>
      </geometry>
    </visual>
  </link>

  <link name="left_thruster_link">
    <visual>
      <origin xyz="0 0 0" rpy="0 0 0"/>
      <geometry>
        <cylinder radius="0.02" length="0.03"/>
      </geometry>
    </visual>
  </link>

  <link name="right_thruster_link">
    <visual>
      <origin xyz="0 0 0" rpy="0 0 0"/>
      <geometry>
        <cylinder radius="0.02" length="0.03"/>
      </geometry>
    </visual>
  </link>

  <joint name="front_thruster_joint" type="revolute">
    <parent link="base_link"/>
    <child link="front_thruster_link"/>
    <limit effort="1000.0" lower="-1.3" upper="1.3" velocity="0.5"/>
    <axis xyz="0 1 0"/>
    <origin xyz="0 0.11 0"/>
  </joint>

  <joint name="back_thruster_joint" type="revolute">
    <parent link="base_link"/>
    <child link="back_thruster_link"/>
    <limit effort="1000.0" lower="-1.3" upper="1.3" velocity="0.5"/>
    <axis xyz="0 1 0"/>
    <origin xyz="0 -0.11 0"/>
  </joint>

  <joint name="left_thruster_joint" type="revolute">
    <parent link="base_link"/>
    <child link="left_thruster_link"/>
    <limit effort="1000.0" lower="-1.3" upper="1.3" velocity="0.5"/>
    <axis xyz="1 0 0"/>
    <origin xyz="-0.09 0 0"/>
  </joint>

  <joint name="right_thruster_joint" type="revolute">
    <parent link="base_link"/>
    <child link="right_thruster_link"/>
    <limit effort="1000.0" lower="-1.3" upper="1.3" velocity="0.5"/>
    <axis xyz="1 0 0"/>
    <origin xyz="0.09 0 0"/>
  </joint>

  <xacro:macro name="thruster_macro" params="namespace thruster_id *origin">
    <link name="thruster_${thruster_id}">

      <inertial>
        <mass value="0.001" />
        <origin xyz="0 0 0" rpy="0 0 0"/>
        <inertia ixx="0.000000017" ixy="0.0" ixz="0.0"
               iyy="0.000000017" iyz="0.0"
               izz="0.000000017" />
      </inertial>
    </link>

    <joint name="thruster_${thruster_id}_joint" type="fixed">
      <xacro:insert_block name="origin" />
      <axis xyz="1 0 0" />
      <parent link="base_link" />
      <child link="thruster_${thruster_id}" />
    </joint>

    <gazebo>
      <plugin name="${namespace}_${thruster_id}_thruster_model" filename="libthruster_ros_plugin.so">
        <linkName>thruster_${thruster_id}</linkName>
        <jointName>thruster_${thruster_id}_joint</jointName>
        <thrusterID>${thruster_id}</thrusterID>
        <gain>5</gain>
        <dynamics>
          <type>FirstOrder</type>
          <timeConstant>0.2</timeConstant>
        </dynamics>
        <conversion>
          <type>Basic</type>
          <rotorConstant>0.00001</rotorConstant>
        </conversion>
      </plugin>
    </gazebo>

    <gazebo reference="thruster_${thruster_id}">
      <selfCollide>false</selfCollide>
    </gazebo>
</xacro:macro>

<xacro:thruster_macro
  namespace=""
  thruster_id="0">
<origin xyz="0 0 0" rpy="0 0 0" />
</xacro:thruster_macro>

</robot>
