<?xml version="1.0"?>
<robot xmlns:xacro="http://www.ros.org/wiki/xacro">

  <xacro:macro name="thruster_macro" params="robot_namespace thruster_id *axis *origin">
      <link name="${robot_namespace}/thruster_${thruster_id}">
        <visual>
          <origin xyz="0 0 0" rpy="0 1.5707963 0"/>
          <geometry>
            <cylinder radius="0.02" length="0.03"/>
          </geometry>
        </visual>
        <inertial>
          <mass value="0.001" />
          <origin xyz="0 0 0" rpy="0 0 0"/>
          <inertia ixx="0.000000017" ixy="0.0" ixz="0.0"
                 iyy="0.000000017" iyz="0.0"
                 izz="0.000000017" />
        </inertial>
      </link>

      <joint name="${robot_namespace}/thruster_${thruster_id}_joint" type="revolute">
        <xacro:insert_block name="axis" />
        <xacro:insert_block name="origin" />
        <parent link="${robot_namespace}/base_link" />
        <child link="${robot_namespace}/thruster_${thruster_id}" />
        <limit effort="1000.0" lower="-1.3" upper="1.3" velocity="0.5"/>
      </joint>

      <transmission name="${robot_namespace}/thruster_${thruster_id}_transmission">
        <type>transmission_interface/SimpleTransmission</type>
        <joint name="${robot_namespace}/thruster_${thruster_id}_joint">
          <hardwareInterface>hardware_interface/PositionJointInterface</hardwareInterface>
        </joint>
        <actuator name="${robot_namespace}/thruster_${thruster_id}_servo">
          <hardwareInterface>hardware_interface/PositionJointInterface</hardwareInterface>
          <mechanicalReduction>1</mechanicalReduction>
        </actuator>
      </transmission>

      <gazebo>
        <plugin name="${robot_namespace}_${thruster_id}_thruster_model" filename="libthruster_ros_plugin.so">
          <linkName>${robot_namespace}/thruster_${thruster_id}</linkName>
          <jointName>${robot_namespace}/thruster_${thruster_id}_joint</jointName>
          <thrusterID>${thruster_id}</thrusterID>
          <gain>5</gain>
          <dynamics>
            <type>FirstOrder</type>
            <timeConstant>0.2</timeConstant>
          </dynamics>
          <conversion>
            <type>Basic</type>
            <rotorConstant>0.00001</rotorConstant>
          </conversion>
        </plugin>
      </gazebo>

      <gazebo reference="${robot_namespace}/thruster_${thruster_id}">
        <selfCollide>false</selfCollide>
      </gazebo>
  </xacro:macro>

</robot>
